Workbook

Sheet Sheet1
A3: Row Labels | B3: Sum of Tasks_Assigned | C3: Sum of Tasks_completed | D3: Completion Rate
A4: E001 | B4: 42 | C4: 40 | D4: =C4/B4 -> 0.95238095
A5: E002 | B5: 48 | C5: 45 | D5: =C5/B5 -> 0.9375
A6: E003 | B6: 55 | C6: 48 | D6: =C6/B6 -> 0.87272727
A7: E004 | B7: 38 | C7: 36 | D7: =C7/B7 -> 0.94736842
A8: E005 | B8: 45 | C8: 43 | D8: =C8/B8 -> 0.95555556
A9: E006 | B9: 58 | C9: 51 | D9: =C9/B9 -> 0.87931034
A10: E007 | B10: 47 | C10: 44 | D10: =C10/B10 -> 0.93617021
A11: E008 | B11: 51 | C11: 47 | D11: =C11/B11 -> 0.92156863
A12: E009 | B12: 63 | C12: 52 | D12: =C12/B12 -> 0.82539683
A13: E010 | B13: 40 | C13: 38 | D13: =C13/B13 -> 0.95
A14: E011 | B14: 54 | C14: 50 | D14: =C14/B14 -> 0.92592593
A15: E012 | B15: 49 | C15: 45 | D15: =C15/B15 -> 0.91836735
... A52: E049 | B52: 53 | C52: 47 | D52: =C52/B52 -> 0.88679245
A53: E050
A54: Grand Total | B54: 2566 | C54: 2323

Sheet Raw_Data
A1: Employee_ID | B1: Employee_Name | C1: Department | D1: Role | E1: Month | F1: Work_Hours | G1: Expected_Hours | H1: Tasks_Assigned | I1: Tasks_completed | J1: Overtime_Hours | K1: Meeting_Hours | L1: Leave_days | M1: Satisfaction_Score | N1: Performance_Score | O1: Deadline_Misses | P1: After_Hours_Messages | Q1: Manager | R1: Competion Rate
A2: E001 | B2: Aarav Sharma | C2: IT | D2: Software Analyst | E2: Jan | F2: 168 | G2: 168 | H2: 42 | I2: 40 | J2: 4 | K2: 18 | L2: 1 | M2: 8 | N2: 8 | O2: 1 | P2: 5 | Q2: Vikram Singh | R2: =I2/H2 -> 0.95238095
A3: E002 | B3: Priya Mehta | C3: Finance | D3: Financial Analyst | E3: Feb | F3: 176 | G3: 168 | H3: 48 | I3: 45 | J3: 8 | K3: 22 | L3: 0 | M3: 6 | N3: 7 | O3: 2 | P3: 8 | Q3: Vikram Singh | R3: =I3/H3 -> 0.9375
A4: E003 | B4: Rahul Verma | C4: Marketing | D4: Marketing Specialist | E4: Mar | F4: 182 | G4: 168 | H4: 55 | I4: 48 | J4: 16 | K4: 27 | L4: 0 | M4: 5 | N4: 7 | O4: 3 | P4: 12 | Q4: Priya Kapoor | R4: =I4/H4 -> 0.87272727
A5: E004 | B5: Neha Kapoor | C5: Human Resources | D5: HR Executive | E5: Apr | F5: 160 | G5: 168 | H5: 38 | I5: 36 | J5: 2 | K5: 15 | L5: 2 | M5: 9 | N5: 9 | O5: 0 | P5: 3 | Q5: Priya Kapoor | R5: =I5/H5 -> 0.94736842
A6: E005 | B6: Arjun Malhotra | C6: Operations | D6: Operations Analyst | E6: May | F6: 171 | G6: 168 | H6: 45 | I6: 43 | J6: 6 | K6: 20 | L6: 1 | M6: 7 | N6: 8 | O6: 1 | P6: 6 | Q6: Rahul Mehta | R6: =I6/H6 -> 0.95555556
A7: E006 | B7: Simran Kaur | C7: Sales | D7: Sales Executive | E7: Jun | F7: 185 | G7: 168 | H7: 58 | I7: 51 | J7: 18 | K7: 30 | L7: 0 | M7: 4 | N7: 6 | O7: 4 | P7: 15 | Q7: Rahul Mehta | R7: =I7/H7 -> 0.87931034
A8: E007 | B8: Rohan Gupta | C8: IT | D8: Data Analyst | E8: Jul | F8: 172 | G8: 168 | H8: 47 | I8: 44 | J8: 5 | K8: 19 | L8: 1 | M8: 8 | N8: 8 | O8: 1 | P8: 5 | Q8: Vikram Singh | R8: =I8/H8 -> 0.93617021
A9: E008 | B9: Ananya Singh | C9: Finance | D9: Accountant | E9: Aug | F9: 178 | G9: 168 | H9: 51 | I9: 47 | J9: 10 | K9: 24 | L9: 0 | M9: 7 | N9: 8 | O9: 2 | P9: 9 | Q9: Vikram Singh | R9: =I9/H9 -> 0.92156863
A10: E009 | B10: Vivek Sharma | C10: Marketing | D10: Marketing Analyst | E10: Sep | F10: 190 | G10: 168 | H10: 63 | I10: 52 | J10: 24 | K10: 31 | L10: 0 | M10: 4 | N10: 6 | O10: 5 | P10: 18 | Q10: Priya Kapoor | R10: =I10/H10 -> 0.82539683
A11: E010 | B11: Ishita Patel | C11: Human Resources | D11: HR Specialist | E11: Oct | F11: 165 | G11: 168 | H11: 40 | I11: 38 | J11: 3 | K11: 17 | L11: 2 | M11: 8 | N11: 9 | O11: 0 | P11: 4 | Q11: Priya Kapoor | R11: =I11/H11 -> 0.95
A12: E011 | B12: Karan Arora | C12: Operations | D12: Operations Executive | E12: Nov | F12: 180 | G12: 168 | H12: 54 | I12: 50 | J12: 14 | K12: 26 | L12: 1 | M12: 5 | N12: 7 | O12: 3 | P12: 11 | Q12: Rahul Mehta | R12: =I12/H12 -> 0.92592593
A13: E012 | B13: Mehak Sethi | C13: Sales | D13: Sales Analyst | E13: Dec | F13: 174 | G13: 168 | H13: 49 | I13: 45 | J13: 9 | K13: 21 | L13: 0 | M13: 6 | N13: 8 | O13: 2 | P13: 7 | Q13: Rahul Mehta | R13: =I13/H13 -> 0.91836735
... A50: E049 | B50: Akash Mehta | C50: IT | D50: Business Analyst | E50: Jan | F50: 177 | G50: 168 | H50: 53 | I50: 47 | J50: 9 | K50: 22 | L50: 1 | M50: 6 | N50: 8 | O50: 2 | P50: 8 | Q50: Vikram Singh | R50: =I50/H50 -> 0.88679245
L51: 0

Sheet Calculations
A1: Employee_ID | B1: Employee_Name | C1: Department | D1: Month | E1: Workload_Utilisation | F1: Task_Complete_Rate | G1: Overtime_Rate | H1: Meeting_Load | I1: Performance_Risk | J1: Satisfaction_Risk | K1: Dedaline_Risk | L1: After_Hours_Risk | M1: Workload_Risk_Score | N1: Risk_Level | O1: Primary_Risk_Driver
A2: =Raw_Data!A2 -> E001 | B2: =Raw_Data!B2 -> Aarav Sharma | C2: =Raw_Data!C2 -> IT | D2: =Raw_Data!E2 -> Jan | E2: =Raw_Data!F2/Raw_Data!G2 -> 1 | F2: =IFERROR(Raw_Data!I2/Raw_Data!H2,0) -> 0.95238095 | G2: =IFERROR(Raw_Data!J2/Raw_Data!F2,0) -> 0.023809524 | H2: =IFERROR(Raw_Data!K2/Raw_Data!F2,0) -> 0.10714286 | I2: =IF(Raw_Data!N2<3,"High",IF(Raw_Data!N2<4,"Medium","Low")) -> Low | J2: =IF(Raw_Data!M2<3,"High",IF(Raw_Data!M2<4,"Medium","Low")) -> Low | K2: =IF(Raw_Data!O2>=3,"High",IF(Raw_Data!O2>=1,"Medium","Low")) -> Medium | L2: =IF(Raw_Data!P2>=10,"High",IF(Raw_Data!P2>=5,"Medium","Low")) -> Medium | M2: =(E2*0.2)+(F2*0.2)+(G2*0.2)+(H2*0.2)+((I2="High")*0.2) -> 0.41666667 | N2: =IF(M2>=0.7,"High",IF(M2>=0.4,"Medium","Low")) -> Medium | O2: {=IF(COUNTIF(I2:L2,"High")>0,INDEX({"Performance","Satisfaction","Deadline","After-Hours"},MATCH("High",I2:L2,0)),IF(COUNTIF(I2:L2,"Medium")>0,INDEX({"Performance","Satisfaction","Deadline","After-Hours"},MATCH("Medium",I2:L2,0)),"None"))} -> Deadline
A3: =Raw_Data!A3 -> E002 | B3: =Raw_Data!B3 -> Priya Mehta | C3: =Raw_Data!C3 -> Finance | D3: =Raw_Data!E3 -> Feb | E3: =Raw_Data!F3/Raw_Data!G3 -> 1.047619 | F3: =IFERROR(Raw_Data!I3/Raw_Data!H3,0) -> 0.9375 | G3: =IFERROR(Raw_Data!J3/Raw_Data!F3,0) -> 0.045454545 | H3: =IFERROR(Raw_Data!K3/Raw_Data!F3,0) -> 0.125 | I3: =IF(Raw_Data!N3<3,"High",IF(Raw_Data!N3<4,"Medium","Low")) -> Low | J3: =IF(Raw_Data!M3<3,"High",IF(Raw_Data!M3<4,"Medium","Low")) -> Low | K3: =IF(Raw_Data!O3>=3,"High",IF(Raw_Data!O3>=1,"Medium","Low")) -> Medium | L3: =IF(Raw_Data!P3>=10,"High",IF(Raw_Data!P3>=5,"Medium","Low")) -> Medium | M3: =(E3*0.2)+(F3*0.2)+(G3*0.2)+(H3*0.2)+((I3="High")*0.2) -> 0.43111472 | N3: =IF(M3>=0.7,"High",IF(M3>=0.4,"Medium","Low")) -> Medium | O3: {=IF(COUNTIF(I3:L3,"High")>0,INDEX({"Performance","Satisfaction","Deadline","After-Hours"},MATCH("High",I3:L3,0)),IF(COUNTIF(I3:L3,"Medium")>0,INDEX({"Performance","Satisfaction","Deadline","After-Hours"},MATCH("Medium",I3:L3,0)),"None"))} -> Deadline
A4: =Raw_Data!A4 -> E003 | B4: =Raw_Data!B4 -> Rahul Verma | C4: =Raw_Data!C4 -> Marketing | D4: =Raw_Data!E4 -> Mar | E4: =Raw_Data!F4/Raw_Data!G4 -> 1.0833333 | F4: =IFERROR(Raw_Data!I4/Raw_Data!H4,0) -> 0.87272727 | G4: =IFERROR(Raw_Data!J4/Raw_Data!F4,0) -> 0.087912088 | H4: =IFERROR(Raw_Data!K4/Raw_Data!F4,0) -> 0.14835165 | I4: =IF(Raw_Data!N4<3,"High",IF(Raw_Data!N4<4,"Medium","Low")) -> Low | J4: =IF(Raw_Data!M4<3,"High",IF(Raw_Data!M4<4,"Medium","Low")) -> Low | K4: =IF(Raw_Data!O4>=3,"High",IF(Raw_Data!O4>=1,"Medium","Low")) -> High | L4: =IF(Raw_Data!P4>=10,"High",IF(Raw_Data!P4>=5,"Medium","Low")) -> High | M4: =(E4*0.2)+(F4*0.2)+(G4*0.2)+(H4*0.2)+((I4="High")*0.2) -> 0.43846487 | N4: =IF(M4>=0.7,"High",IF(M4>=0.4,"Medium","Low")) -> Medium | O4: {=IF(COUNTIF(I4:L4,"High")>0,INDEX({"Performance","Satisfaction","Deadline","After-Hours"},MATCH("High",I4:L4,0)),IF(COUNTIF(I4:L4,"Medium")>0,INDEX({"Performance","Satisfaction","Deadline","After-Hours"},MATCH("Medium",I4:L4,0)),"None"))} -> Deadline
A5: =Raw_Data!A5 -> E004 | B5: =Raw_Data!B5 -> Neha Kapoor | C5: =Raw_Data!C5 -> Human Resources | D5: =Raw_Data!E5 -> Apr | E5: =Raw_Data!F5/Raw_Data!G5 -> 0.95238095 | F5: =IFERROR(Raw_Data!I5/Raw_Data!H5,0) -> 0.94736842 | G5: =IFERROR(Raw_Data!J5/Raw_Data!F5,0) -> 0.0125 | H5: =IFERROR(Raw_Data!K5/Raw_Data!F5,0) -> 0.09375 | I5: =IF(Raw_Data!N5<3,"High",IF(Raw_Data!N5<4,"Medium","Low")) -> Low | J5: =IF(Raw_Data!M5<3,"High",IF(Raw_Data!M5<4,"Medium","Low")) -> Low | K5: =IF(Raw_Data!O5>=3,"High",IF(Raw_Data!O5>=1,"Medium","Low")) -> Low | L5: =IF(Raw_Data!P5>=10,"High",IF(Raw_Data!P5>=5,"Medium","Low")) -> Low | M5: =(E5*0.2)+(F5*0.2)+(G5*0.2)+(H5*0.2)+((I5="High")*0.2) -> 0.40119987 | N5: =IF(M5>=0.7,"High",IF(M5>=0.4,"Medium","Low")) -> Medium | O5: {=IF(COUNTIF(I5:L5,"High")>0,INDEX({"Performance","Satisfaction","Deadline","After-Hours"},MATCH("High",I5:L5,0)),IF(COUNTIF(I5:L5,"Medium")>0,INDEX({"Performance","Satisfaction","Deadline","After-Hours"},MATCH("Medium",I5:L5,0)),"None"))} -> None
A6: =Raw_Data!A6 -> E005 | B6: =Raw_Data!B6 -> Arjun Malhotra | C6: =Raw_Data!C6 -> Operations | D6: =Raw_Data!E6 -> May | E6: =Raw_Data!F6/Raw_Data!G6 -> 1.0178571 | F6: =IFERROR(Raw_Data!I6/Raw_Data!H6,0) -> 0.95555556 | G6: =IFERROR(Raw_Data!J6/Raw_Data!F6,0) -> 0.035087719 | H6: =IFERROR(Raw_Data!K6/Raw_Data!F6,0) -> 0.11695906 | I6: =IF(Raw_Data!N6<3,"High",IF(Raw_Data!N6<4,"Medium","Low")) -> Low | J6: =IF(Raw_Data!M6<3,"High",IF(Raw_Data!M6<4,"Medium","Low")) -> Low | K6: =IF(Raw_Data!O6>=3,"High",IF(Raw_Data!O6>=1,"Medium","Low")) -> Medium | L6: =IF(Raw_Data!P6>=10,"High",IF(Raw_Data!P6>=5,"Medium","Low")) -> Medium | M6: =(E6*0.2)+(F6*0.2)+(G6*0.2)+(H6*0.2)+((I6="High")*0.2) -> 0.4250919 | N6: =IF(M6>=0.7,"High",IF(M6>=0.4,"Medium","Low")) -> Medium | O6: {=IF(COUNTIF(I6:L6,"High")>0,INDEX({"Performance","Satisfaction","Deadline","After-Hours"},MATCH("High",I6:L6,0)),IF(COUNTIF(I6:L6,"Medium")>0,INDEX({"Performance","Satisfaction","Deadline","After-Hours"},MATCH("Medium",I6:L6,0)),"None"))} -> Deadline
A7: =Raw_Data!A7 -> E006 | B7: =Raw_Data!B7 -> Simran Kaur | C7: =Raw_Data!C7 -> Sales | D7: =Raw_Data!E7 -> Jun | E7: =Raw_Data!F7/Raw_Data!G7 -> 1.1011905 | F7: =IFERROR(Raw_Data!I7/Raw_Data!H7,0) -> 0.87931034 | G7: =IFERROR(Raw_Data!J7/Raw_Data!F7,0) -> 0.097297297 | H7: =IFERROR(Raw_Data!K7/Raw_Data!F7,0) -> 0.16216216 | I7: =IF(Raw_Data!N7<3,"High",IF(Raw_Data!N7<4,"Medium","Low")) -> Low | J7: =IF(Raw_Data!M7<3,"High",IF(Raw_Data!M7<4,"Medium","Low")) -> Low | K7: =IF(Raw_Data!O7>=3,"High",IF(Raw_Data!O7>=1,"Medium","Low")) -> High | L7: =IF(Raw_Data!P7>=10,"High",IF(Raw_Data!P7>=5,"Medium","Low")) -> High | M7: =(E7*0.2)+(F7*0.2)+(G7*0.2)+(H7*0.2)+((I7="High")*0.2) -> 0.44799206 | N7: =IF(M7>=0.7,"High",IF(M7>=0.4,"Medium","Low")) -> Medium | O7: {=IF(COUNTIF(I7:L7,"High")>0,INDEX({"Performance","Satisfaction","Deadline","After-Hours"},MATCH("High",I7:L7,0)),IF(COUNTIF(I7:L7,"Medium")>0,INDEX({"Performance","Satisfaction","Deadline","After-Hours"},MATCH("Medium",I7:L7,0)),"None"))} -> Deadline
A8: =Raw_Data!A8 -> E007 | B8: =Raw_Data!B8 -> Rohan Gupta | C8: =Raw_Data!C8 -> IT | D8: =Raw_Data!E8 -> Jul | E8: =Raw_Data!F8/Raw_Data!G8 -> 1.0238095 | F8: =IFERROR(Raw_Data!I8/Raw_Data!H8,0) -> 0.93617021 | G8: =IFERROR(Raw_Data!J8/Raw_Data!F8,0) -> 0.029069767 | H8: =IFERROR(Raw_Data!K8/Raw_Data!F8,0) -> 0.11046512 | I8: =IF(Raw_Data!N8<3,"High",IF(Raw_Data!N8<4,"Medium","Low")) -> Low | J8: =IF(Raw_Data!M8<3,"High",IF(Raw_Data!M8<4,"Medium","Low")) -> Low | K8: =IF(Raw_Data!O8>=3,"High",IF(Raw_Data!O8>=1,"Medium","Low")) -> Medium | L8: =IF(Raw_Data!P8>=10,"High",IF(Raw_Data!P8>=5,"Medium","Low")) -> Medium | M8: =(E8*0.2)+(F8*0.2)+(G8*0.2)+(H8*0.2)+((I8="High")*0.2) -> 0.41990292 | N8: =IF(M8>=0.7,"High",IF(M8>=0.4,"Medium","Low")) -> Medium | O8: {=IF(COUNTIF(I8:L8,"High")>0,INDEX({"Performance","Satisfaction","Deadline","After-Hours"},MATCH("High",I8:L8,0)),IF(COUNTIF(I8:L8,"Medium")>0,INDEX({"Performance","Satisfaction","Deadline","After-Hours"},MATCH("Medium",I8:L8,0)),"None"))} -> Deadline
A9: =Raw_Data!A9 -> E008 | B9: =Raw_Data!B9 -> Ananya Singh | C9: =Raw_Data!C9 -> Finance | D9: =Raw_Data!E9 -> Aug | E9: =Raw_Data!F9/Raw_Data!G9 -> 1.0595238 | F9: =IFERROR(Raw_Data!I9/Raw_Data!H9,0) -> 0.92156863 | G9: =IFERROR(Raw_Data!J9/Raw_Data!F9,0) -> 0.056179775 | H9: =IFERROR(Raw_Data!K9/Raw_Data!F9,0) -> 0.13483146 | I9: =IF(Raw_Data!N9<3,"High",IF(Raw_Data!N9<4,"Medium","Low")) -> Low | J9: =IF(Raw_Data!M9<3,"High",IF(Raw_Data!M9<4,"Medium","Low")) -> Low | K9: =IF(Raw_Data!O9>=3,"High",IF(Raw_Data!O9>=1,"Medium","Low")) -> Medium | L9: =IF(Raw_Data!P9>=10,"High",IF(Raw_Data!P9>=5,"Medium","Low")) -> Medium | M9: =(E9*0.2)+(F9*0.2)+(G9*0.2)+(H9*0.2)+((I9="High")*0.2) -> 0.43442073 | N9: =IF(M9>=0.7,"High",IF(M9>=0.4,"Medium","Low")) -> Medium | O9: {=IF(COUNTIF(I9:L9,"High")>0,INDEX({"Performance","Satisfaction","Deadline","After-Hours"},MATCH("High",I9:L9,0)),IF(COUNTIF(I9:L9,"Medium")>0,INDEX({"Performance","Satisfaction","Deadline","After-Hours"},MATCH("Medium",I9:L9,0)),"None"))} -> Deadline
A10: =Raw_Data!A10 -> E009 | B10: =Raw_Data!B10 -> Vivek Sharma | C10: =Raw_Data!C10 -> Marketing | D10: =Raw_Data!E10 -> Sep | E10: =Raw_Data!F10/Raw_Data!G10 -> 1.1309524 | F10: =IFERROR(Raw_Data!I10/Raw_Data!H10,0) -> 0.82539683 | G10: =IFERROR(Raw_Data!J10/Raw_Data!F10,0) -> 0.12631579 | H10: =IFERROR(Raw_Data!K10/Raw_Data!F10,0) -> 0.16315789 | I10: =IF(Raw_Data!N10<3,"High",IF(Raw_Data!N10<4,"Medium","Low")) -> Low | J10: =IF(Raw_Data!M10<3,"High",IF(Raw_Data!M10<4,"Medium","Low")) -> Low | K10: =IF(Raw_Data!O10>=3,"High",IF(Raw_Data!O10>=1,"Medium","Low")) -> High | L10: =IF(Raw_Data!P10>=10,"High",IF(Raw_Data!P10>=5,"Medium","Low")) -> High | M10: =(E10*0.2)+(F10*0.2)+(G10*0.2)+(H10*0.2)+((I10="High")*0.2) -> 0.44916458 | N10: =IF(M10>=0.7,"High",IF(M10>=0.4,"Medium","Low")) -> Medium | O10: {=IF(COUNTIF(I10:L10,"High")>0,INDEX({"Performance","Satisfaction","Deadline","After-Hours"},MATCH("High",I10:L10,0)),IF(COUNTIF(I10:L10,"Medium")>0,INDEX({"Performance","Satisfaction","Deadline","After-Hours"},MATCH("Medium",I10:L10,0)),"None"))} -> Deadline
A11: =Raw_Data!A11 -> E010 | B11: =Raw_Data!B11 -> Ishita Patel | C11: =Raw_Data!C11 -> Human Resources | D11: =Raw_Data!E11 -> Oct | E11: =Raw_Data!F11/Raw_Data!G11 -> 0.98214286 | F11: =IFERROR(Raw_Data!I11/Raw_Data!H11,0) -> 0.95 | G11: =IFERROR(Raw_Data!J11/Raw_Data!F11,0) -> 0.018181818 | H11: =IFERROR(Raw_Data!K11/Raw_Data!F11,0) -> 0.1030303 | I11: =IF(Raw_Data!N11<3,"High",IF(Raw_Data!N11<4,"Medium","Low")) -> Low | J11: =IF(Raw_Data!M11<3,"High",IF(Raw_Data!M11<4,"Medium","Low")) -> Low | K11: =IF(Raw_Data!O11>=3,"High",IF(Raw_Data!O11>=1,"Medium","Low")) -> Low | L11: =IF(Raw_Data!P11>=10,"High",IF(Raw_Data!P11>=5,"Medium","Low")) -> Low | M11: =(E11*0.2)+(F11*0.2)+(G11*0.2)+(H11*0.2)+((I11="High")*0.2) -> 0.410671 | N11: =IF(M11>=0.7,"High",IF(M11>=0.4,"Medium","Low")) -> Medium | O11: {=IF(COUNTIF(I11:L11,"High")>0,INDEX({"Performance","Satisfaction","Deadline","After-Hours"},MATCH("High",I11:L11,0)),IF(COUNTIF(I11:L11,"Medium")>0,INDEX({"Performance","Satisfaction","Deadline","After-Hours"},MATCH("Medium",I11:L11,0)),"None"))} -> None
A12: =Raw_Data!A12 -> E011 | B12: =Raw_Data!B12 -> Karan Arora | C12: =Raw_Data!C12 -> Operations | D12: =Raw_Data!E12 -> Nov | E12: =Raw_Data!F12/Raw_Data!G12 -> 1.0714286 | F12: =IFERROR(Raw_Data!I12/Raw_Data!H12,0) -> 0.92592593 | G12: =IFERROR(Raw_Data!J12/Raw_Data!F12,0) -> 0.077777778 | H12: =IFERROR(Raw_Data!K12/Raw_Data!F12,0) -> 0.14444444 | I12: =IF(Raw_Data!N12<3,"High",IF(Raw_Data!N12<4,"Medium","Low")) -> Low | J12: =IF(Raw_Data!M12<3,"High",IF(Raw_Data!M12<4,"Medium","Low")) -> Low | K12: =IF(Raw_Data!O12>=3,"High",IF(Raw_Data!O12>=1,"Medium","Low")) -> High | L12: =IF(Raw_Data!P12>=10,"High",IF(Raw_Data!P12>=5,"Medium","Low")) -> High | M12: =(E12*0.2)+(F12*0.2)+(G12*0.2)+(H12*0.2)+((I12="High")*0.2) -> 0.44391534 | N12: =IF(M12>=0.7,"High",IF(M12>=0.4,"Medium","Low")) -> Medium | O12: {=IF(COUNTIF(I12:L12,"High")>0,INDEX({"Performance","Satisfaction","Deadline","After-Hours"},MATCH("High",I12:L12,0)),IF(COUNTIF(I12:L12,"Medium")>0,INDEX({"Performance","Satisfaction","Deadline","After-Hours"},MATCH("Medium",I12:L12,0)),"None"))} -> Deadline
A13: =Raw_Data!A13 -> E012 | B13: =Raw_Data!B13 -> Mehak Sethi | C13: =Raw_Data!C13 -> Sales | D13: =Raw_Data!E13 -> Dec | E13: =Raw_Data!F13/Raw_Data!G13 -> 1.0357143 | F13: =IFERROR(Raw_Data!I13/Raw_Data!H13,0) -> 0.91836735 | G13: =IFERROR(Raw_Data!J13/Raw_Data!F13,0) -> 0.051724138 | H13: =IFERROR(Raw_Data!K13/Raw_Data!F13,0) -> 0.12068966 | I13: =IF(Raw_Data!N13<3,"High",IF(Raw_Data!N13<4,"Medium","Low")) -> Low | J13: =IF(Raw_Data!M13<3,"High",IF(Raw_Data!M13<4,"Medium","Low")) -> Low | K13: =IF(Raw_Data!O13>=3,"High",IF(Raw_Data!O13>=1,"Medium","Low")) -> Medium | L13: =IF(Raw_Data!P13>=10,"High",IF(Raw_Data!P13>=5,"Medium","Low")) -> Medium | M13: =(E13*0.2)+(F13*0.2)+(G13*0.2)+(H13*0.2)+((I13="High")*0.2) -> 0.42529909 | N13: =IF(M13>=0.7,"High",IF(M13>=0.4,"Medium","Low")) -> Medium | O13: {=IF(COUNTIF(I13:L13,"High")>0,INDEX({"Performance","Satisfaction","Deadline","After-Hours"},MATCH("High",I13:L13,0)),IF(COUNTIF(I13:L13,"Medium")>0,INDEX({"Performance","Satisfaction","Deadline","After-Hours"},MATCH("Medium",I13:L13,0)),"None"))} -> Deadline
... A50: =Raw_Data!A50 -> E049 | B50: =Raw_Data!B50 -> Akash Mehta | C50: =Raw_Data!C50 -> IT | D50: =Raw_Data!E50 -> Jan | E50: =Raw_Data!F50/Raw_Data!G50 -> 1.0535714 | F50: =IFERROR(Raw_Data!I50/Raw_Data!H50,0) -> 0.88679245 | G50: =IFERROR(Raw_Data!J50/Raw_Data!F50,0) -> 0.050847458 | H50: =IFERROR(Raw_Data!K50/Raw_Data!F50,0) -> 0.12429379 | I50: =IF(Raw_Data!N50<3,"High",IF(Raw_Data!N50<4,"Medium","Low")) -> Low | J50: =IF(Raw_Data!M50<3,"High",IF(Raw_Data!M50<4,"Medium","Low")) -> Low | K50: =IF(Raw_Data!O50>=3,"High",IF(Raw_Data!O50>=1,"Medium","Low")) -> Medium | L50: =IF(Raw_Data!P50>=10,"High",IF(Raw_Data!P50>=5,"Medium","Low")) -> Medium | M50: =(E50*0.2)+(F50*0.2)+(G50*0.2)+(H50*0.2)+((I50="High")*0.2) -> 0.42310102 | N50: =IF(M50>=0.7,"High",IF(M50>=0.4,"Medium","Low")) -> Medium | O50: {=IF(COUNTIF(I50:L50,"High")>0,INDEX({"Performance","Satisfaction","Deadline","After-Hours"},MATCH("High",I50:L50,0)),IF(COUNTIF(I50:L50,"Medium")>0,INDEX({"Performance","Satisfaction","Deadline","After-Hours"},MATCH("Medium",I50:L50,0)),"None"))} -> Deadline

Sheet Dashboard
E1: WORKLOAD PULSE
E2: Employee Workload Early Warning System
E5: WORKFORCE RISK OVERVIEW
A7: HIGH RISK EMPLOYEES | B7: =COUNTIF(Calculations!N:N,"High") -> 0 | D7: MEDIUM RISK EMPLOYEES | E7: =COUNTIF(Calculations!N:N,"Medium") -> 49 | G7: LOW RISK EMPLOYEES | H7: =COUNTIF(Calculations!N:N,"Low") -> 0 | J7: TOTAL EMPLOYEES | K7: =COUNTA(Raw_Data!A:A)-1 -> 49
D9: PRIMARY RISK DRIVERS
D11: Risk Driver | E11: Employees Affected
D12: Overtime | E12: =COUNTIF(Calculations!G:G,">=0.1") -> 11
D13: Meeting Load | E13: =COUNTIF(Calculations!H:H,">=0.15") -> 16
D14: Performance | E14: =COUNTIF(Calculations!O:O,"Performance") -> 0
D15: Satisfaction | E15: =COUNTIF(Calculations!O:O,"Satisfaction") -> 1
D16: Deadline Misses | E16: =COUNTIF(Calculations!O:O,"Deadline") -> 38
D17: After-Hours Messages | E17: =COUNTIF(Calculations!O:O,"After-Hours") -> 3
D22: RISK DISTRIBUTION
D24: Risk Level | E24: Employees
D25: High | E25: =COUNTIF(Calculations!N:N,"High") -> 0
D26: Medium | E26: =COUNTIF(Calculations!N:N,"Medium") -> 49
D27: Low | E27: =COUNTIF(Calculations!N:N,"Low") -> 0
D35: WORKLOAD & OVERTIME ANALYSIS
D37: Metric | E37: Average
D38: Work Hours | E38: =AVERAGE(Raw_Data!F:F) -> 177.61224
D39: Overtime Hours | E39: =AVERAGE(Raw_Data!J:J) -> 12.081633
D40: Meeting Hours | E40: =AVERAGE(Raw_Data!K:K) -> 24.265306
D41: Task Completion Rate | E41: =AVERAGE(Calculations!F:F) -> 0.91103027
D43: Work Hours | E43: Overtime Hours | F43: Meeting Hours
D44: 177.61224 | E44: 12.081633 | F44: 24.265306
D48: TASK COMPLETION
D50: Average Task completion Rate | E50: =AVERAGE(tblCalculations[Task_Complete_Rate]) -> 0.91103027
C53: Row Labels | D53: Average of Tasks_completed
C54: E050
C55: E004 | D55: 36
C56: E021 | D56: 37
C57: E042 | D57: 38
C58: E010 | D58: 38
C59: E028 | D59: 39
C60: E033 | D60: 40
C61: E001 | D61: 40
C62: E025 | D62: 41
C63: E038 | D63: 41
C64: E014 | D64: 42
C65: E036 | D65: 42
...
